{
  size: [7, 6, 9],
  entities: [
    {
      nbt: {
        HurtByTimestamp: 0,
        Attributes: [
          {
            Base: 20.0d,
            Name: "generic.maxHealth"
          },
          {
            Base: 0.0d,
            Name: "generic.knockbackResistance"
          },
          {
            Base: 0.5d,
            Name: "generic.movementSpeed"
          },
          {
            Base: 0.0d,
            Name: "generic.armor"
          },
          {
            Base: 16.0d,
            Modifiers: [
              {
                UUIDMost: -8050404301371587461L,
                UUIDLeast: -9042289162618353532L,
                Amount: -0.07807250298271795d,
                Operation: 1,
                Name: "Random spawn bonus"
              }
            ],
            Name: "generic.followRange"
          }
        ],
        Riches: 15,
        ForcedAge: 0,
        Invulnerable: 0b,
        AbsorptionAmount: 0.0f,
        PortalCooldown: 0,
        FallDistance: 0.0f,
        DeathTime: 0s,
        HandDropChances: [0.08500000089406967f, 0.08500000089406967f],
        PersistenceRequired: 1b,
        id: "minecraft:villager",
        Age: 0,
        Motion: [0.0d, -0.0784000015258789d, 0.0d],
        Leashed: 0b,
        Health: 20.0f,
        UUIDLeast: -8404016208519177543L,
        LeftHanded: 0b,
        Air: 300s,
        Dimension: 0,
        Offers: {
          Recipes: [
            {
              maxUses: 7,
              buy: {
                Count: 36b,
                id: "minecraft:rotten_flesh",
                Damage: 0s
              },
              sell: {
                Count: 1b,
                id: "minecraft:emerald",
                Damage: 0s
              },
              uses: 0,
              rewardExp: 1b
            },
            {
              maxUses: 7,
              buy: {
                Count: 9b,
                id: "minecraft:gold_ingot",
                Damage: 0s
              },
              sell: {
                Count: 1b,
                id: "minecraft:emerald",
                Damage: 0s
              },
              uses: 0,
              rewardExp: 1b
            }
          ]
        },
        OnGround: 1b,
        Rotation: [-4.32769775390625f, -3.4165501594543457f],
        HandItems: [
          {},
          {}
        ],
        ArmorDropChances: [0.08500000089406967f, 0.08500000089406967f, 0.08500000089406967f, 0.08500000089406967f],
        Profession: 2,
        UUIDMost: 1009044389481761978L,
        Pos: [-72.5d, 62.0d, -120.5d],
        ArmorItems: [
          {},
          {},
          {},
          {}
        ],
        Fire: -1s,
        CanPickUpLoot: 1b,
        HurtTime: 0s,
        CareerLevel: 1,
        Career: 1,
        Inventory: [],
        Willing: 0b
      },
      blockPos: [2, 1, 1],
      pos: [2.5d, 1.0d, 1.5d]
    },
    {
      nbt: {
        HurtByTimestamp: 125,
        Attributes: [
          {
            Base: 20.0d,
            Name: "generic.maxHealth"
          },
          {
            Base: 0.0d,
            Modifiers: [
              {
                UUIDMost: -1136549371827500916L,
                UUIDLeast: -9185924421726330189L,
                Amount: 0.033586338385064834d,
                Operation: 0,
                Name: "Random spawn bonus"
              }
            ],
            Name: "generic.knockbackResistance"
          },
          {
            Base: 0.23000000417232513d,
            Name: "generic.movementSpeed"
          },
          {
            Base: 2.0d,
            Name: "generic.armor"
          },
          {
            Base: 35.0d,
            Modifiers: [
              {
                UUIDMost: -7187282525081156696L,
                UUIDLeast: -4972655095452447334L,
                Amount: -0.013882809459502736d,
                Operation: 1,
                Name: "Random spawn bonus"
              }
            ],
            Name: "generic.followRange"
          },
          {
            Base: 3.0d,
            Name: "generic.attackDamage"
          },
          {
            Base: 0.08507647017248195d,
            Name: "zombie.spawnReinforcements"
          }
        ],
        Invulnerable: 0b,
        AbsorptionAmount: 0.0f,
        PortalCooldown: 0,
        FallDistance: 0.0f,
        DeathTime: 0s,
        HandDropChances: [0.08500000089406967f, 0.08500000089406967f],
        PersistenceRequired: 1b,
        id: "minecraft:zombie_villager",
        ConversionTime: -1,
        Motion: [0.0d, -0.0784000015258789d, 0.0d],
        Leashed: 0b,
        Health: 19.049999237060547f,
        UUIDLeast: -6631449421406796428L,
        LeftHanded: 0b,
        Air: 300s,
        Dimension: 0,
        OnGround: 1b,
        Rotation: [-95.78887939453125f, 0.0f],
        HandItems: [
          {},
          {}
        ],
        ArmorDropChances: [0.08500000089406967f, 0.08500000089406967f, 0.08500000089406967f, 0.08500000089406967f],
        Profession: 2,
        UUIDMost: 9169347718178752431L,
        CanBreakDoors: 0b,
        Pos: [-70.5d, 62.0d, -120.69999998807907d],
        ArmorItems: [
          {},
          {},
          {},
          {}
        ],
        Fire: -1s,
        CanPickUpLoot: 0b,
        HurtTime: 0s
      },
      blockPos: [4, 1, 1],
      pos: [4.5d, 1.0d, 1.300000011920929d]
    }
  ],
  author: "Searge_DP",
  blocks: [
    {
      pos: [1, 0, 0],
      state: 0
    },
    {
      pos: [2, 0, 0],
      state: 0
    },
    {
      pos: [3, 0, 0],
      state: 0
    },
    {
      pos: [4, 0, 0],
      state: 0
    },
    {
      pos: [5, 0, 0],
      state: 0
    },
    {
      pos: [1, 1, 0],
      state: 1
    },
    {
      pos: [2, 1, 0],
      state: 1
    },
    {
      pos: [3, 1, 0],
      state: 1
    },
    {
      pos: [4, 1, 0],
      state: 1
    },
    {
      pos: [5, 1, 0],
      state: 1
    },
    {
      pos: [1, 2, 0],
      state: 1
    },
    {
      pos: [2, 2, 0],
      state: 1
    },
    {
      pos: [3, 2, 0],
      state: 1
    },
    {
      pos: [4, 2, 0],
      state: 1
    },
    {
      pos: [5, 2, 0],
      state: 1
    },
    {
      pos: [1, 3, 0],
      state: 1
    },
    {
      pos: [2, 3, 0],
      state: 1
    },
    {
      pos: [3, 3, 0],
      state: 1
    },
    {
      pos: [4, 3, 0],
      state: 1
    },
    {
      pos: [5, 3, 0],
      state: 1
    },
    {
      pos: [1, 0, 1],
      state: 0
    },
    {
      pos: [2, 0, 1],
      state: 2
    },
    {
      pos: [3, 0, 1],
      state: 0
    },
    {
      pos: [4, 0, 1],
      state: 2
    },
    {
      pos: [5, 0, 1],
      state: 0
    },
    {
      pos: [1, 1, 1],
      state: 1
    },
    {
      pos: [2, 1, 1],
      state: 3
    },
    {
      pos: [3, 1, 1],
      state: 1
    },
    {
      pos: [4, 1, 1],
      state: 3
    },
    {
      pos: [5, 1, 1],
      state: 1
    },
    {
      pos: [1, 2, 1],
      state: 1
    },
    {
      pos: [2, 2, 1],
      state: 3
    },
    {
      pos: [3, 2, 1],
      state: 1
    },
    {
      pos: [4, 2, 1],
      state: 3
    },
    {
      pos: [5, 2, 1],
      state: 1
    },
    {
      pos: [1, 3, 1],
      state: 1
    },
    {
      pos: [2, 3, 1],
      state: 3
    },
    {
      pos: [3, 3, 1],
      state: 1
    },
    {
      pos: [4, 3, 1],
      state: 3
    },
    {
      pos: [5, 3, 1],
      state: 1
    },
    {
      pos: [2, 4, 1],
      state: 1
    },
    {
      pos: [3, 4, 1],
      state: 1
    },
    {
      pos: [4, 4, 1],
      state: 1
    },
    {
      pos: [1, 0, 2],
      state: 0
    },
    {
      pos: [2, 0, 2],
      state: 1
    },
    {
      pos: [3, 0, 2],
      state: 0
    },
    {
      pos: [4, 0, 2],
      state: 1
    },
    {
      pos: [5, 0, 2],
      state: 0
    },
    {
      pos: [1, 1, 2],
      state: 4
    },
    {
      pos: [3, 1, 2],
      state: 4
    },
    {
      pos: [5, 1, 2],
      state: 4
    },
    {
      pos: [1, 2, 2],
      state: 1
    },
    {
      pos: [3, 2, 2],
      state: 2
    },
    {
      pos: [5, 2, 2],
      state: 1
    },
    {
      pos: [1, 3, 2],
      state: 1
    },
    {
      pos: [2, 3, 2],
      state: 1
    },
    {
      pos: [3, 3, 2],
      state: 1
    },
    {
      pos: [4, 3, 2],
      state: 1
    },
    {
      pos: [5, 3, 2],
      state: 1
    },
    {
      pos: [2, 4, 2],
      state: 1
    },
    {
      pos: [3, 4, 2],
      state: 1
    },
    {
      pos: [4, 4, 2],
      state: 1
    },
    {
      pos: [1, 0, 3],
      state: 5
    },
    {
      pos: [2, 0, 3],
      state: 1
    },
    {
      pos: [3, 0, 3],
      state: 6
    },
    {
      pos: [4, 0, 3],
      state: 1
    },
    {
      pos: [5, 0, 3],
      state: 7
    },
    {
      pos: [0, 1, 3],
      state: 4
    },
    {
      pos: [2, 1, 3],
      state: 3
    },
    {
      pos: [3, 1, 3],
      state: 3
    },
    {
      pos: [4, 1, 3],
      state: 3
    },
    {
      pos: [5, 1, 3],
      state: 3
    },
    {
      pos: [6, 1, 3],
      state: 4
    },
    {
      pos: [0, 2, 3],
      state: 2
    },
    {
      pos: [1, 2, 3],
      state: 3
    },
    {
      pos: [2, 2, 3],
      state: 3
    },
    {
      pos: [4, 2, 3],
      state: 3
    },
    {
      pos: [5, 2, 3],
      state: 3
    },
    {
      pos: [6, 2, 3],
      state: 1
    },
    {
      pos: [0, 3, 3],
      state: 1
    },
    {
      pos: [2, 3, 3],
      state: 3
    },
    {
      pos: [4, 3, 3],
      state: 3
    },
    {
      pos: [5, 3, 3],
      state: 3
    },
    {
      pos: [6, 3, 3],
      state: 1
    },
    {
      pos: [1, 4, 3],
      state: 1
    },
    {
      pos: [2, 4, 3],
      state: 1
    },
    {
      pos: [3, 4, 3],
      state: 1
    },
    {
      pos: [4, 4, 3],
      state: 1
    },
    {
      pos: [5, 4, 3],
      state: 1
    },
    {
      pos: [1, 0, 4],
      state: 1
    },
    {
      pos: [2, 0, 4],
      state: 8
    },
    {
      pos: [3, 0, 4],
      state: 1
    },
    {
      pos: [4, 0, 4],
      state: 1
    },
    {
      pos: [5, 0, 4],
      state: 1
    },
    {
      pos: [0, 1, 4],
      state: 4
    },
    {
      pos: [2, 1, 4],
      state: 3
    },
    {
      pos: [3, 1, 4],
      state: 3
    },
    {
      pos: [4, 1, 4],
      state: 3
    },
    {
      pos: [6, 1, 4],
      state: 4
    },
    {
      pos: [0, 2, 4],
      state: 1
    },
    {
      pos: [1, 2, 4],
      state: 3
    },
    {
      pos: [2, 2, 4],
      state: 3
    },
    {
      pos: [3, 2, 4],
      state: 3
    },
    {
      pos: [4, 2, 4],
      state: 3
    },
    {
      pos: [5, 2, 4],
      state: 3
    },
    {
      pos: [6, 2, 4],
      state: 1
    },
    {
      pos: [0, 3, 4],
      state: 8
    },
    {
      pos: [1, 3, 4],
      state: 3
    },
    {
      pos: [2, 3, 4],
      state: 3
    },
    {
      pos: [3, 3, 4],
      state: 3
    },
    {
      pos: [4, 3, 4],
      state: 3
    },
    {
      pos: [5, 3, 4],
      state: 3
    },
    {
      pos: [6, 3, 4],
      state: 1
    },
    {
      pos: [1, 4, 4],
      state: 1
    },
    {
      pos: [2, 4, 4],
      state: 1
    },
    {
      pos: [3, 4, 4],
      state: 1
    },
    {
      pos: [4, 4, 4],
      state: 1
    },
    {
      pos: [5, 4, 4],
      state: 1
    },
    {
      pos: [1, 0, 5],
      state: 6
    },
    {
      pos: [2, 0, 5],
      state: 1
    },
    {
      pos: [3, 0, 5],
      state: 6
    },
    {
      pos: [4, 0, 5],
      state: 1
    },
    {
      pos: [5, 0, 5],
      state: 6
    },
    {
      pos: [0, 1, 5],
      state: 4
    },
    {
      pos: [1, 1, 5],
      state: 3
    },
    {
      pos: [2, 1, 5],
      state: 3
    },
    {
      pos: [3, 1, 5],
      state: 3
    },
    {
      pos: [4, 1, 5],
      state: 3
    },
    {
      pos: [6, 1, 5],
      state: 4
    },
    {
      pos: [0, 2, 5],
      state: 1
    },
    {
      pos: [1, 2, 5],
      state: 3
    },
    {
      pos: [2, 2, 5],
      state: 3
    },
    {
      pos: [3, 2, 5],
      state: 3
    },
    {
      pos: [4, 2, 5],
      state: 3
    },
    {
      pos: [5, 2, 5],
      state: 3
    },
    {
      pos: [6, 2, 5],
      state: 2
    },
    {
      pos: [0, 3, 5],
      state: 1
    },
    {
      pos: [1, 3, 5],
      state: 3
    },
    {
      pos: [2, 3, 5],
      state: 3
    },
    {
      pos: [3, 3, 5],
      state: 3
    },
    {
      pos: [4, 3, 5],
      state: 3
    },
    {
      pos: [5, 3, 5],
      state: 3
    },
    {
      pos: [6, 3, 5],
      state: 1
    },
    {
      pos: [1, 4, 5],
      state: 1
    },
    {
      pos: [2, 4, 5],
      state: 1
    },
    {
      pos: [3, 4, 5],
      state: 7
    },
    {
      pos: [4, 4, 5],
      state: 1
    },
    {
      pos: [5, 4, 5],
      state: 1
    },
    {
      pos: [1, 0, 6],
      state: 1
    },
    {
      pos: [2, 0, 6],
      state: 1
    },
    {
      pos: [3, 0, 6],
      state: 1
    },
    {
      pos: [4, 0, 6],
      state: 1
    },
    {
      pos: [5, 0, 6],
      state: 8
    },
    {
      pos: [0, 1, 6],
      state: 4
    },
    {
      pos: [2, 1, 6],
      state: 3
    },
    {
      pos: [3, 1, 6],
      state: 3
    },
    {
      pos: [4, 1, 6],
      state: 3
    },
    {
      pos: [6, 1, 6],
      state: 4
    },
    {
      pos: [0, 2, 6],
      state: 2
    },
    {
      pos: [2, 2, 6],
      state: 3
    },
    {
      pos: [3, 2, 6],
      state: 3
    },
    {
      pos: [4, 2, 6],
      state: 3
    },
    {
      pos: [6, 2, 6],
      state: 8
    },
    {
      pos: [0, 3, 6],
      state: 1
    },
    {
      pos: [1, 3, 6],
      state: 3
    },
    {
      pos: [2, 3, 6],
      state: 3
    },
    {
      pos: [3, 3, 6],
      state: 3
    },
    {
      pos: [4, 3, 6],
      state: 3
    },
    {
      pos: [5, 3, 6],
      state: 3
    },
    {
      pos: [6, 3, 6],
      state: 1
    },
    {
      pos: [1, 4, 6],
      state: 1
    },
    {
      pos: [2, 4, 6],
      state: 8
    },
    {
      pos: [3, 4, 6],
      state: 1
    },
    {
      pos: [4, 4, 6],
      state: 1
    },
    {
      pos: [5, 4, 6],
      state: 1
    },
    {
      pos: [3, 5, 6],
      state: 1
    },
    {
      pos: [1, 0, 7],
      state: 6
    },
    {
      pos: [2, 0, 7],
      state: 1
    },
    {
      pos: [3, 0, 7],
      state: 6
    },
    {
      pos: [4, 0, 7],
      state: 1
    },
    {
      pos: [5, 0, 7],
      state: 6
    },
    {
      pos: [0, 1, 7],
      state: 4
    },
    {
      pos: [1, 1, 7],
      state: 3
    },
    {
      pos: [2, 1, 7],
      state: 3
    },
    {
      pos: [3, 1, 7],
      state: 3
    },
    {
      pos: [4, 1, 7],
      state: 3
    },
    {
      pos: [6, 1, 7],
      state: 4
    },
    {
      pos: [0, 2, 7],
      state: 1
    },
    {
      pos: [1, 2, 7],
      state: 3
    },
    {
      pos: [2, 2, 7],
      state: 3
    },
    {
      pos: [4, 2, 7],
      state: 3
    },
    {
      pos: [6, 2, 7],
      state: 1
    },
    {
      pos: [0, 3, 7],
      state: 1
    },
    {
      pos: [1, 3, 7],
      state: 3
    },
    {
      pos: [5, 3, 7],
      state: 3
    },
    {
      pos: [6, 3, 7],
      state: 1
    },
    {
      pos: [1, 4, 7],
      state: 1
    },
    {
      pos: [2, 4, 7],
      state: 1
    },
    {
      pos: [4, 4, 7],
      state: 1
    },
    {
      pos: [5, 4, 7],
      state: 1
    },
    {
      pos: [2, 5, 7],
      state: 1
    },
    {
      pos: [4, 5, 7],
      state: 1
    },
    {
      pos: [1, 1, 8],
      state: 4
    },
    {
      pos: [2, 1, 8],
      state: 9
    },
    {
      pos: [3, 1, 8],
      state: 4
    },
    {
      pos: [4, 1, 8],
      state: 4
    },
    {
      pos: [5, 1, 8],
      state: 4
    },
    {
      pos: [1, 2, 8],
      state: 8
    },
    {
      pos: [2, 2, 8],
      state: 1
    },
    {
      pos: [3, 2, 8],
      state: 2
    },
    {
      pos: [4, 2, 8],
      state: 1
    },
    {
      pos: [5, 2, 8],
      state: 2
    },
    {
      pos: [1, 3, 8],
      state: 1
    },
    {
      pos: [2, 3, 8],
      state: 1
    },
    {
      pos: [3, 3, 8],
      state: 1
    },
    {
      pos: [4, 3, 8],
      state: 1
    },
    {
      pos: [5, 3, 8],
      state: 1
    },
    {
      pos: [2, 4, 8],
      state: 1
    },
    {
      pos: [3, 4, 8],
      state: 1
    },
    {
      pos: [4, 4, 8],
      state: 1
    },
    {
      pos: [3, 5, 8],
      state: 1
    },
    {
      nbt: {
        Text4: "{\"text\":\"\"}",
        Text3: "{\"text\":\"----\\u003e\"}",
        Text2: "{\"text\":\"\\u003c----\"}",
        Text1: "{\"text\":\"\"}",
        id: "Sign"
      },
      pos: [3, 2, 3],
      state: 10
    },
    {
      nbt: {
        Items: [],
        id: "Chest",
        Lock: ""
      },
      pos: [1, 1, 6],
      state: 11
    },
    {
      nbt: {
        metadata: "chest",
        mirror: "NONE",
        ignoreEntities: 0b,
        author: "Searge",
        rotation: "NONE",
        mode: "DATA",
        posX: 1,
        posY: 1,
        sizeX: 0,
        posZ: 1,
        name: "",
        id: "Structure",
        sizeY: 0,
        sizeZ: 0
      },
      pos: [1, 2, 6],
      state: 12
    },
    {
      nbt: {
        Fuel: 0b,
        Items: [
          {
            Slot: 1b,
            Count: 1b,
            id: "minecraft:splash_potion",
            tag: {
              Potion: "minecraft:weakness"
            },
            Damage: 0s
          }
        ],
        id: "Cauldron",
        BrewTime: 0s,
        Lock: ""
      },
      pos: [5, 2, 6],
      state: 13
    },
    {
      nbt: {
        Item: "minecraft:cactus",
        Data: 0,
        id: "FlowerPot"
      },
      pos: [5, 2, 7],
      state: 14
    },
    {
      pos: [2, 1, 2],
      state: 15
    },
    {
      pos: [4, 1, 2],
      state: 15
    },
    {
      pos: [2, 2, 2],
      state: 15
    },
    {
      pos: [4, 2, 2],
      state: 15
    },
    {
      pos: [1, 1, 3],
      state: 16
    },
    {
      pos: [1, 3, 3],
      state: 17
    },
    {
      pos: [3, 3, 3],
      state: 18
    },
    {
      pos: [1, 1, 4],
      state: 16
    },
    {
      pos: [5, 1, 4],
      state: 19
    },
    {
      pos: [5, 1, 5],
      state: 20
    },
    {
      pos: [5, 1, 6],
      state: 21
    },
    {
      pos: [5, 1, 7],
      state: 22
    },
    {
      pos: [3, 2, 7],
      state: 23
    },
    {
      pos: [2, 3, 7],
      state: 24
    },
    {
      pos: [3, 3, 7],
      state: 23
    },
    {
      pos: [4, 3, 7],
      state: 24
    },
    {
      pos: [3, 4, 7],
      state: 23
    },
    {
      pos: [3, 5, 7],
      state: 23
    }
  ],
  palette: [
    {
      Properties: {
        variant: "stone"
      },
      Name: "minecraft:stone"
    },
    {
      Properties: {
        variant: "stonebrick"
      },
      Name: "minecraft:stonebrick"
    },
    {
      Properties: {
        variant: "cracked_stonebrick"
      },
      Name: "minecraft:stonebrick"
    },
    {
      Name: "minecraft:air"
    },
    {
      Properties: {
        variant: "mossy_stonebrick"
      },
      Name: "minecraft:stonebrick"
    },
    {
      Properties: {
        variant: "smooth_andesite"
      },
      Name: "minecraft:stone"
    },
    {
      Properties: {
        variant: "chiseled_stonebrick"
      },
      Name: "minecraft:stonebrick"
    },
    {
      Properties: {
        variant: "chiseled_brick"
      },
      Name: "minecraft:monster_egg"
    },
    {
      Properties: {
        variant: "stone_brick"
      },
      Name: "minecraft:monster_egg"
    },
    {
      Properties: {
        variant: "mossy_brick"
      },
      Name: "minecraft:monster_egg"
    },
    {
      Properties: {
        facing: "south"
      },
      Name: "minecraft:wall_sign"
    },
    {
      Properties: {
        facing: "east"
      },
      Name: "minecraft:chest"
    },
    {
      Properties: {
        mode: "data"
      },
      Name: "minecraft:structure_block"
    },
    {
      Properties: {
        has_bottle_0: "false",
        has_bottle_1: "true",
        has_bottle_2: "false"
      },
      Name: "minecraft:brewing_stand"
    },
    {
      Properties: {
        contents: "empty",
        legacy_data: "0"
      },
      Name: "minecraft:flower_pot"
    },
    {
      Properties: {
        east: "false",
        south: "false",
        north: "false",
        west: "false"
      },
      Name: "minecraft:iron_bars"
    },
    {
      Properties: {
        color: "red"
      },
      Name: "minecraft:carpet"
    },
    {
      Name: "minecraft:web"
    },
    {
      Properties: {
        facing: "south"
      },
      Name: "minecraft:torch"
    },
    {
      Properties: {
        level: "2"
      },
      Name: "minecraft:cauldron"
    },
    {
      Properties: {
        half: "top",
        shape: "straight",
        facing: "north"
      },
      Name: "minecraft:spruce_stairs"
    },
    {
      Properties: {
        half: "top",
        variant: "spruce"
      },
      Name: "minecraft:wooden_slab"
    },
    {
      Properties: {
        half: "top",
        shape: "straight",
        facing: "south"
      },
      Name: "minecraft:spruce_stairs"
    },
    {
      Properties: {
        facing: "north"
      },
      Name: "minecraft:ladder"
    },
    {
      Properties: {
        facing: "north"
      },
      Name: "minecraft:torch"
    }
  ],
  version: 1
}