{
  size: [7, 7, 7],
  entities: [],
  author: "",
  blocks: [
    {
      pos: [0, 0, 0],
      state: 0
    },
    {
      pos: [1, 0, 0],
      state: 0
    },
    {
      pos: [2, 0, 0],
      state: 0
    },
    {
      pos: [3, 0, 0],
      state: 0
    },
    {
      pos: [4, 0, 0],
      state: 0
    },
    {
      pos: [5, 0, 0],
      state: 0
    },
    {
      pos: [6, 0, 0],
      state: 0
    },
    {
      pos: [0, 1, 0],
      state: 0
    },
    {
      pos: [1, 1, 0],
      state: 0
    },
    {
      pos: [2, 1, 0],
      state: 0
    },
    {
      pos: [3, 1, 0],
      state: 0
    },
    {
      pos: [4, 1, 0],
      state: 0
    },
    {
      pos: [5, 1, 0],
      state: 0
    },
    {
      pos: [6, 1, 0],
      state: 0
    },
    {
      pos: [0, 2, 0],
      state: 0
    },
    {
      pos: [1, 2, 0],
      state: 0
    },
    {
      pos: [2, 2, 0],
      state: 0
    },
    {
      pos: [3, 2, 0],
      state: 0
    },
    {
      pos: [4, 2, 0],
      state: 0
    },
    {
      pos: [5, 2, 0],
      state: 0
    },
    {
      pos: [6, 2, 0],
      state: 0
    },
    {
      pos: [0, 3, 0],
      state: 1
    },
    {
      pos: [1, 3, 0],
      state: 1
    },
    {
      pos: [2, 3, 0],
      state: 1
    },
    {
      pos: [3, 3, 0],
      state: 1
    },
    {
      pos: [4, 3, 0],
      state: 1
    },
    {
      pos: [5, 3, 0],
      state: 1
    },
    {
      pos: [6, 3, 0],
      state: 1
    },
    {
      pos: [0, 4, 0],
      state: 0
    },
    {
      pos: [1, 4, 0],
      state: 0
    },
    {
      pos: [2, 4, 0],
      state: 0
    },
    {
      pos: [3, 4, 0],
      state: 0
    },
    {
      pos: [4, 4, 0],
      state: 0
    },
    {
      pos: [5, 4, 0],
      state: 0
    },
    {
      pos: [6, 4, 0],
      state: 0
    },
    {
      pos: [0, 5, 0],
      state: 0
    },
    {
      pos: [1, 5, 0],
      state: 0
    },
    {
      pos: [2, 5, 0],
      state: 0
    },
    {
      pos: [4, 5, 0],
      state: 0
    },
    {
      pos: [5, 5, 0],
      state: 0
    },
    {
      pos: [6, 5, 0],
      state: 0
    },
    {
      pos: [0, 6, 0],
      state: 0
    },
    {
      pos: [1, 6, 0],
      state: 0
    },
    {
      pos: [2, 6, 0],
      state: 0
    },
    {
      pos: [3, 6, 0],
      state: 0
    },
    {
      pos: [4, 6, 0],
      state: 0
    },
    {
      pos: [5, 6, 0],
      state: 0
    },
    {
      pos: [6, 6, 0],
      state: 0
    },
    {
      pos: [0, 0, 1],
      state: 0
    },
    {
      pos: [1, 0, 1],
      state: 0
    },
    {
      pos: [2, 0, 1],
      state: 0
    },
    {
      pos: [3, 0, 1],
      state: 0
    },
    {
      pos: [4, 0, 1],
      state: 0
    },
    {
      pos: [5, 0, 1],
      state: 0
    },
    {
      pos: [6, 0, 1],
      state: 0
    },
    {
      pos: [0, 1, 1],
      state: 0
    },
    {
      pos: [1, 1, 1],
      state: 0
    },
    {
      pos: [2, 1, 1],
      state: 0
    },
    {
      pos: [3, 1, 1],
      state: 0
    },
    {
      pos: [4, 1, 1],
      state: 0
    },
    {
      pos: [5, 1, 1],
      state: 0
    },
    {
      pos: [6, 1, 1],
      state: 0
    },
    {
      pos: [0, 2, 1],
      state: 0
    },
    {
      pos: [1, 2, 1],
      state: 0
    },
    {
      pos: [2, 2, 1],
      state: 0
    },
    {
      pos: [3, 2, 1],
      state: 0
    },
    {
      pos: [4, 2, 1],
      state: 0
    },
    {
      pos: [5, 2, 1],
      state: 0
    },
    {
      pos: [6, 2, 1],
      state: 0
    },
    {
      pos: [0, 3, 1],
      state: 1
    },
    {
      pos: [1, 3, 1],
      state: 1
    },
    {
      pos: [2, 3, 1],
      state: 1
    },
    {
      pos: [3, 3, 1],
      state: 1
    },
    {
      pos: [4, 3, 1],
      state: 1
    },
    {
      pos: [5, 3, 1],
      state: 1
    },
    {
      pos: [6, 3, 1],
      state: 1
    },
    {
      pos: [0, 4, 1],
      state: 0
    },
    {
      pos: [1, 4, 1],
      state: 0
    },
    {
      pos: [2, 4, 1],
      state: 2
    },
    {
      pos: [3, 4, 1],
      state: 2
    },
    {
      pos: [4, 4, 1],
      state: 2
    },
    {
      pos: [5, 4, 1],
      state: 0
    },
    {
      pos: [6, 4, 1],
      state: 0
    },
    {
      pos: [0, 5, 1],
      state: 0
    },
    {
      pos: [1, 5, 1],
      state: 0
    },
    {
      pos: [2, 5, 1],
      state: 2
    },
    {
      pos: [3, 5, 1],
      state: 3
    },
    {
      pos: [4, 5, 1],
      state: 2
    },
    {
      pos: [5, 5, 1],
      state: 0
    },
    {
      pos: [6, 5, 1],
      state: 0
    },
    {
      pos: [0, 6, 1],
      state: 0
    },
    {
      pos: [1, 6, 1],
      state: 0
    },
    {
      pos: [2, 6, 1],
      state: 2
    },
    {
      pos: [3, 6, 1],
      state: 2
    },
    {
      pos: [4, 6, 1],
      state: 2
    },
    {
      pos: [5, 6, 1],
      state: 0
    },
    {
      pos: [6, 6, 1],
      state: 0
    },
    {
      pos: [0, 0, 2],
      state: 0
    },
    {
      pos: [1, 0, 2],
      state: 0
    },
    {
      pos: [2, 0, 2],
      state: 0
    },
    {
      pos: [3, 0, 2],
      state: 0
    },
    {
      pos: [4, 0, 2],
      state: 0
    },
    {
      pos: [5, 0, 2],
      state: 0
    },
    {
      pos: [6, 0, 2],
      state: 0
    },
    {
      pos: [0, 1, 2],
      state: 0
    },
    {
      pos: [1, 1, 2],
      state: 0
    },
    {
      pos: [2, 1, 2],
      state: 0
    },
    {
      pos: [3, 1, 2],
      state: 0
    },
    {
      pos: [4, 1, 2],
      state: 0
    },
    {
      pos: [5, 1, 2],
      state: 0
    },
    {
      pos: [6, 1, 2],
      state: 0
    },
    {
      pos: [0, 2, 2],
      state: 0
    },
    {
      pos: [1, 2, 2],
      state: 0
    },
    {
      pos: [2, 2, 2],
      state: 0
    },
    {
      pos: [3, 2, 2],
      state: 0
    },
    {
      pos: [4, 2, 2],
      state: 0
    },
    {
      pos: [5, 2, 2],
      state: 0
    },
    {
      pos: [6, 2, 2],
      state: 0
    },
    {
      pos: [0, 3, 2],
      state: 1
    },
    {
      pos: [1, 3, 2],
      state: 1
    },
    {
      pos: [2, 3, 2],
      state: 0
    },
    {
      pos: [3, 3, 2],
      state: 0
    },
    {
      pos: [4, 3, 2],
      state: 0
    },
    {
      pos: [5, 3, 2],
      state: 1
    },
    {
      pos: [6, 3, 2],
      state: 1
    },
    {
      pos: [0, 4, 2],
      state: 0
    },
    {
      pos: [1, 4, 2],
      state: 2
    },
    {
      pos: [2, 4, 2],
      state: 0
    },
    {
      pos: [4, 4, 2],
      state: 0
    },
    {
      pos: [5, 4, 2],
      state: 2
    },
    {
      pos: [6, 4, 2],
      state: 0
    },
    {
      pos: [0, 5, 2],
      state: 0
    },
    {
      pos: [1, 5, 2],
      state: 2
    },
    {
      pos: [2, 5, 2],
      state: 0
    },
    {
      pos: [3, 5, 2],
      state: 0
    },
    {
      pos: [4, 5, 2],
      state: 0
    },
    {
      pos: [5, 5, 2],
      state: 2
    },
    {
      pos: [6, 5, 2],
      state: 0
    },
    {
      pos: [0, 6, 2],
      state: 0
    },
    {
      pos: [1, 6, 2],
      state: 2
    },
    {
      pos: [2, 6, 2],
      state: 0
    },
    {
      pos: [3, 6, 2],
      state: 0
    },
    {
      pos: [4, 6, 2],
      state: 0
    },
    {
      pos: [5, 6, 2],
      state: 2
    },
    {
      pos: [6, 6, 2],
      state: 0
    },
    {
      pos: [0, 0, 3],
      state: 0
    },
    {
      pos: [1, 0, 3],
      state: 0
    },
    {
      pos: [2, 0, 3],
      state: 0
    },
    {
      pos: [3, 0, 3],
      state: 0
    },
    {
      pos: [4, 0, 3],
      state: 0
    },
    {
      pos: [5, 0, 3],
      state: 0
    },
    {
      pos: [6, 0, 3],
      state: 0
    },
    {
      pos: [0, 1, 3],
      state: 0
    },
    {
      pos: [1, 1, 3],
      state: 0
    },
    {
      pos: [2, 1, 3],
      state: 0
    },
    {
      pos: [3, 1, 3],
      state: 0
    },
    {
      pos: [4, 1, 3],
      state: 0
    },
    {
      pos: [5, 1, 3],
      state: 0
    },
    {
      pos: [6, 1, 3],
      state: 0
    },
    {
      pos: [0, 2, 3],
      state: 0
    },
    {
      pos: [1, 2, 3],
      state: 0
    },
    {
      pos: [2, 2, 3],
      state: 0
    },
    {
      pos: [3, 2, 3],
      state: 0
    },
    {
      pos: [4, 2, 3],
      state: 0
    },
    {
      pos: [5, 2, 3],
      state: 0
    },
    {
      pos: [6, 2, 3],
      state: 0
    },
    {
      pos: [0, 3, 3],
      state: 1
    },
    {
      pos: [1, 3, 3],
      state: 1
    },
    {
      pos: [3, 3, 3],
      state: 0
    },
    {
      pos: [4, 3, 3],
      state: 0
    },
    {
      pos: [5, 3, 3],
      state: 1
    },
    {
      pos: [6, 3, 3],
      state: 1
    },
    {
      pos: [0, 4, 3],
      state: 0
    },
    {
      pos: [1, 4, 3],
      state: 2
    },
    {
      pos: [2, 4, 3],
      state: 0
    },
    {
      pos: [3, 4, 3],
      state: 0
    },
    {
      pos: [4, 4, 3],
      state: 0
    },
    {
      pos: [5, 4, 3],
      state: 2
    },
    {
      pos: [6, 4, 3],
      state: 0
    },
    {
      pos: [1, 5, 3],
      state: 4
    },
    {
      pos: [2, 5, 3],
      state: 0
    },
    {
      pos: [3, 5, 3],
      state: 0
    },
    {
      pos: [5, 5, 3],
      state: 4
    },
    {
      pos: [0, 6, 3],
      state: 0
    },
    {
      pos: [1, 6, 3],
      state: 2
    },
    {
      pos: [2, 6, 3],
      state: 0
    },
    {
      pos: [3, 6, 3],
      state: 0
    },
    {
      pos: [4, 6, 3],
      state: 0
    },
    {
      pos: [5, 6, 3],
      state: 2
    },
    {
      pos: [6, 6, 3],
      state: 0
    },
    {
      pos: [0, 0, 4],
      state: 0
    },
    {
      pos: [1, 0, 4],
      state: 0
    },
    {
      pos: [2, 0, 4],
      state: 0
    },
    {
      pos: [4, 0, 4],
      state: 0
    },
    {
      pos: [5, 0, 4],
      state: 0
    },
    {
      pos: [6, 0, 4],
      state: 0
    },
    {
      pos: [0, 1, 4],
      state: 0
    },
    {
      pos: [1, 1, 4],
      state: 0
    },
    {
      pos: [2, 1, 4],
      state: 0
    },
    {
      pos: [4, 1, 4],
      state: 0
    },
    {
      pos: [5, 1, 4],
      state: 0
    },
    {
      pos: [6, 1, 4],
      state: 0
    },
    {
      pos: [0, 2, 4],
      state: 0
    },
    {
      pos: [1, 2, 4],
      state: 0
    },
    {
      pos: [2, 2, 4],
      state: 0
    },
    {
      pos: [4, 2, 4],
      state: 0
    },
    {
      pos: [5, 2, 4],
      state: 0
    },
    {
      pos: [6, 2, 4],
      state: 0
    },
    {
      pos: [0, 3, 4],
      state: 1
    },
    {
      pos: [1, 3, 4],
      state: 1
    },
    {
      pos: [2, 3, 4],
      state: 0
    },
    {
      pos: [3, 3, 4],
      state: 0
    },
    {
      pos: [4, 3, 4],
      state: 0
    },
    {
      pos: [5, 3, 4],
      state: 1
    },
    {
      pos: [6, 3, 4],
      state: 1
    },
    {
      pos: [0, 4, 4],
      state: 0
    },
    {
      pos: [1, 4, 4],
      state: 2
    },
    {
      pos: [2, 4, 4],
      state: 0
    },
    {
      pos: [3, 4, 4],
      state: 0
    },
    {
      pos: [4, 4, 4],
      state: 0
    },
    {
      pos: [5, 4, 4],
      state: 2
    },
    {
      pos: [6, 4, 4],
      state: 0
    },
    {
      pos: [0, 5, 4],
      state: 0
    },
    {
      pos: [1, 5, 4],
      state: 2
    },
    {
      pos: [2, 5, 4],
      state: 0
    },
    {
      pos: [3, 5, 4],
      state: 0
    },
    {
      pos: [4, 5, 4],
      state: 0
    },
    {
      pos: [5, 5, 4],
      state: 2
    },
    {
      pos: [6, 5, 4],
      state: 0
    },
    {
      pos: [0, 6, 4],
      state: 0
    },
    {
      pos: [1, 6, 4],
      state: 2
    },
    {
      pos: [2, 6, 4],
      state: 0
    },
    {
      pos: [4, 6, 4],
      state: 0
    },
    {
      pos: [5, 6, 4],
      state: 2
    },
    {
      pos: [6, 6, 4],
      state: 0
    },
    {
      pos: [0, 0, 5],
      state: 0
    },
    {
      pos: [1, 0, 5],
      state: 0
    },
    {
      pos: [2, 0, 5],
      state: 0
    },
    {
      pos: [3, 0, 5],
      state: 2
    },
    {
      pos: [4, 0, 5],
      state: 0
    },
    {
      pos: [5, 0, 5],
      state: 0
    },
    {
      pos: [6, 0, 5],
      state: 0
    },
    {
      pos: [0, 1, 5],
      state: 0
    },
    {
      pos: [1, 1, 5],
      state: 0
    },
    {
      pos: [2, 1, 5],
      state: 0
    },
    {
      pos: [3, 1, 5],
      state: 2
    },
    {
      pos: [4, 1, 5],
      state: 0
    },
    {
      pos: [5, 1, 5],
      state: 0
    },
    {
      pos: [6, 1, 5],
      state: 0
    },
    {
      pos: [0, 2, 5],
      state: 0
    },
    {
      pos: [1, 2, 5],
      state: 0
    },
    {
      pos: [2, 2, 5],
      state: 0
    },
    {
      pos: [3, 2, 5],
      state: 2
    },
    {
      pos: [4, 2, 5],
      state: 0
    },
    {
      pos: [5, 2, 5],
      state: 0
    },
    {
      pos: [6, 2, 5],
      state: 0
    },
    {
      pos: [0, 3, 5],
      state: 1
    },
    {
      pos: [1, 3, 5],
      state: 1
    },
    {
      pos: [2, 3, 5],
      state: 1
    },
    {
      pos: [3, 3, 5],
      state: 1
    },
    {
      pos: [4, 3, 5],
      state: 1
    },
    {
      pos: [5, 3, 5],
      state: 1
    },
    {
      pos: [6, 3, 5],
      state: 1
    },
    {
      pos: [0, 4, 5],
      state: 0
    },
    {
      pos: [1, 4, 5],
      state: 0
    },
    {
      pos: [2, 4, 5],
      state: 2
    },
    {
      pos: [3, 4, 5],
      state: 2
    },
    {
      pos: [4, 4, 5],
      state: 2
    },
    {
      pos: [5, 4, 5],
      state: 0
    },
    {
      pos: [6, 4, 5],
      state: 0
    },
    {
      pos: [0, 5, 5],
      state: 0
    },
    {
      pos: [1, 5, 5],
      state: 0
    },
    {
      pos: [2, 5, 5],
      state: 2
    },
    {
      pos: [3, 5, 5],
      state: 3
    },
    {
      pos: [4, 5, 5],
      state: 2
    },
    {
      pos: [5, 5, 5],
      state: 0
    },
    {
      pos: [6, 5, 5],
      state: 0
    },
    {
      pos: [0, 6, 5],
      state: 0
    },
    {
      pos: [1, 6, 5],
      state: 0
    },
    {
      pos: [2, 6, 5],
      state: 2
    },
    {
      pos: [3, 6, 5],
      state: 2
    },
    {
      pos: [4, 6, 5],
      state: 2
    },
    {
      pos: [5, 6, 5],
      state: 0
    },
    {
      pos: [6, 6, 5],
      state: 0
    },
    {
      pos: [0, 0, 6],
      state: 0
    },
    {
      pos: [1, 0, 6],
      state: 0
    },
    {
      pos: [2, 0, 6],
      state: 0
    },
    {
      pos: [3, 0, 6],
      state: 0
    },
    {
      pos: [4, 0, 6],
      state: 0
    },
    {
      pos: [5, 0, 6],
      state: 0
    },
    {
      pos: [6, 0, 6],
      state: 0
    },
    {
      pos: [0, 1, 6],
      state: 0
    },
    {
      pos: [1, 1, 6],
      state: 0
    },
    {
      pos: [2, 1, 6],
      state: 0
    },
    {
      pos: [3, 1, 6],
      state: 0
    },
    {
      pos: [4, 1, 6],
      state: 0
    },
    {
      pos: [5, 1, 6],
      state: 0
    },
    {
      pos: [6, 1, 6],
      state: 0
    },
    {
      pos: [0, 2, 6],
      state: 0
    },
    {
      pos: [1, 2, 6],
      state: 0
    },
    {
      pos: [2, 2, 6],
      state: 0
    },
    {
      pos: [3, 2, 6],
      state: 0
    },
    {
      pos: [4, 2, 6],
      state: 0
    },
    {
      pos: [5, 2, 6],
      state: 0
    },
    {
      pos: [6, 2, 6],
      state: 0
    },
    {
      pos: [0, 3, 6],
      state: 1
    },
    {
      pos: [1, 3, 6],
      state: 1
    },
    {
      pos: [2, 3, 6],
      state: 1
    },
    {
      pos: [3, 3, 6],
      state: 1
    },
    {
      pos: [4, 3, 6],
      state: 1
    },
    {
      pos: [5, 3, 6],
      state: 1
    },
    {
      pos: [6, 3, 6],
      state: 1
    },
    {
      pos: [0, 4, 6],
      state: 0
    },
    {
      pos: [1, 4, 6],
      state: 0
    },
    {
      pos: [2, 4, 6],
      state: 0
    },
    {
      pos: [3, 4, 6],
      state: 0
    },
    {
      pos: [4, 4, 6],
      state: 0
    },
    {
      pos: [5, 4, 6],
      state: 0
    },
    {
      pos: [6, 4, 6],
      state: 0
    },
    {
      pos: [0, 5, 6],
      state: 0
    },
    {
      pos: [1, 5, 6],
      state: 0
    },
    {
      pos: [2, 5, 6],
      state: 0
    },
    {
      pos: [4, 5, 6],
      state: 0
    },
    {
      pos: [5, 5, 6],
      state: 0
    },
    {
      pos: [6, 5, 6],
      state: 0
    },
    {
      pos: [0, 6, 6],
      state: 0
    },
    {
      pos: [1, 6, 6],
      state: 0
    },
    {
      pos: [2, 6, 6],
      state: 0
    },
    {
      pos: [3, 6, 6],
      state: 0
    },
    {
      pos: [4, 6, 6],
      state: 0
    },
    {
      pos: [5, 6, 6],
      state: 0
    },
    {
      pos: [6, 6, 6],
      state: 0
    },
    {
      pos: [3, 5, 0],
      state: 5
    },
    {
      pos: [3, 4, 2],
      state: 6
    },
    {
      pos: [2, 3, 3],
      state: 6
    },
    {
      pos: [0, 5, 3],
      state: 7
    },
    {
      pos: [4, 5, 3],
      state: 6
    },
    {
      pos: [6, 5, 3],
      state: 8
    },
    {
      pos: [3, 0, 4],
      state: 9
    },
    {
      pos: [3, 1, 4],
      state: 9
    },
    {
      pos: [3, 2, 4],
      state: 9
    },
    {
      pos: [3, 6, 4],
      state: 6
    },
    {
      pos: [3, 5, 6],
      state: 10
    }
  ],
  palette: [
    {
      Name: "minecraft:air"
    },
    {
      Name: "minecraft:purpur_block"
    },
    {
      Properties: {
        axis: "y"
      },
      Name: "minecraft:purpur_pillar"
    },
    {
      Properties: {
        axis: "z"
      },
      Name: "minecraft:purpur_pillar"
    },
    {
      Properties: {
        axis: "x"
      },
      Name: "minecraft:purpur_pillar"
    },
    {
      Properties: {
        half: "top",
        shape: "straight",
        facing: "south"
      },
      Name: "minecraft:purpur_stairs"
    },
    {
      Properties: {
        half: "bottom",
        variant: "default"
      },
      Name: "minecraft:purpur_slab"
    },
    {
      Properties: {
        half: "top",
        shape: "straight",
        facing: "east"
      },
      Name: "minecraft:purpur_stairs"
    },
    {
      Properties: {
        half: "top",
        shape: "straight",
        facing: "west"
      },
      Name: "minecraft:purpur_stairs"
    },
    {
      Properties: {
        facing: "north"
      },
      Name: "minecraft:ladder"
    },
    {
      Properties: {
        half: "top",
        shape: "straight",
        facing: "north"
      },
      Name: "minecraft:purpur_stairs"
    }
  ],
  version: 1
}